<?xml version="1.0" encoding="utf-8"?>
<robot name="Q1P01_urdf">
  <mujoco>
    <compiler meshdir="../meshes" discardvisual="false" />
  </mujoco>
<!-- [CAUTION] uncomment when convert to mujoco -->
  <!-- <link name="world"></link>
  <joint name="floating_base_joint" type="floating">
    <parent link="world" />
    <child link="torso_link" />
  </joint> -->
<!-- base -->
  <link name="torso_link">
    <inertial>
      <origin xyz="0.0009164 -6.3E-06 0.27347" rpy="0 0 0"/>
      <mass value="9.7"/>
      <inertia ixx="0.87949" ixy="-2.57E-05" ixz="-0.0014233" iyy="0.88111" iyz="-0.000167" izz="0.085877"/>
    </inertial>
    <visual>
      <origin xyz="0 0 0" rpy="0 0 0"/>
      <geometry>
        <mesh filename="meshes/torso_link.STL"/>
      </geometry>
      <material name="">
        <color rgba="0.79216 0.81961 0.93333 1"/>
      </material>
    </visual>
    <collision>
      <origin xyz="-0.03 0 0.25" rpy="0 0 0"/>
      <geometry>
        <box size="0.16 0.16 0.4"/>
      
        <!-- <mesh filename="meshes/torso_link.STL"/> -->
      </geometry>
    </collision>
  </link>
<!-- Left arm -->
  <link name="L_shoulder_pitch_link">
    <inertial>
      <origin xyz="-0.003348 -0.010925 -1.7E-06" rpy="0 0 0"/>
      <mass value="1.52"/>
      <inertia ixx="0.002528" ixy="-5E-07" ixz="0" iyy="0.0015488" iyz="-4E-07" izz="0.0023225"/>
    </inertial>
    <visual>
      <origin xyz="0 0 0" rpy="-0.2618 0 0"/>
      <geometry>
        <mesh filename="meshes/L_shoulder_pitch_link.STL"/>
      </geometry>
      <material name="">
        <color rgba="0.79216 0.81961 0.93333 1"/>
      </material>
    </visual>
    <collision>
      <origin xyz="0 0 0" rpy="1.570796327 0 1.570796327"/>
      <geometry>
        <!-- <mesh filename="meshes/L_shoulder_pitch_link.STL"/> -->
        <!-- <cylinder radius="0.01" length="0.02"/> -->
        <cylinder radius="0.045" length="0.07"/>
      </geometry>
    </collision>
  </link>
  <!-- CRA-RI60-80 -->
  <joint name="L_shoulder_pitch_joint" type="revolute">
    <origin xyz="0 0.21252 0.3773" rpy="0.2618 0 0" />
    <parent link="torso_link" />
    <child link="L_shoulder_pitch_link" />
    <axis xyz="0 1 0" />
    <limit lower="-1.57" upper="1.57" effort="42" velocity="8.58701992" />
  </joint>
  <link name="L_shoulder_roll_link">
    <inertial>
      <origin xyz="-0.0032511 0.0010542 -0.057652" rpy="0 0 0" />
      <mass value="0.75" />
      <inertia ixx="0.0047765" ixy="-4E-07" ixz="1.89E-05" iyy="0.0052242" iyz="9.7E-06" izz="0.0014127" />
    </inertial>
    <visual>
      <origin xyz="0 0 0" rpy="-0.2618 0 0" />
      <geometry>
        <mesh filename="meshes/L_shoulder_roll_link.STL" />
      </geometry>
      <material name="">
        <color rgba="0.79216 0.81961 0.93333 1" />
      </material>
    </visual>
    <collision>
      <origin xyz="0 -0.001 -0.09" rpy="-0.2618 0 0" />
      <geometry>
        <cylinder radius="0.04" length="0.07"/>
      </geometry>
    </collision>
  </link>
  <!-- CRA-RI60-80 -->
  <joint name="L_shoulder_roll_joint" type="revolute">
    <origin xyz="0 0 0" rpy="0 0 0" />
    <parent link="L_shoulder_pitch_link" />
    <child link="L_shoulder_roll_link" />
    <axis xyz="1 0 0" />
    <limit lower="-0.785" upper="0.785" effort="42" velocity="8.58701992" />
  </joint>
  <link name="L_shoulder_yaw_link">
    <inertial>
      <origin xyz="-0.0031672 -0.0008248 0.048205" rpy="0 0 0" />
      <mass value="1.87" />
      <inertia ixx="0.010037" ixy="-3E-07" ixz="2.6E-06" iyy="0.009945" iyz="7.3E-05" izz="0.0016816" />
    </inertial>
    <visual>
      <origin xyz="0 0 0" rpy="0 0 1.57" />
      <geometry>
        <mesh filename="meshes/L_shoulder_yaw_link.STL" />
      </geometry>
      <material name="">
        <color rgba="0.79216 0.81961 0.93333 1" />
      </material>
    </visual>
    <collision>
      <origin xyz="0 0 0.08" rpy="0 0 0" />
      <geometry>
        <cylinder radius="0.04" length="0.07"/>
      </geometry>
    </collision>
  </link>
  <!-- CRA-RI50-70 -->
  <joint name="L_shoulder_yaw_joint" type="revolute">
    <origin xyz="0 -0.043208 -0.25042" rpy="-0.2618 0.0 0.0" />
    <!-- <origin xyz="0 -0.043208 -0.25042" rpy="-0.2618 0 0" /> -->
    <parent link="L_shoulder_roll_link" />
    <child link="L_shoulder_yaw_link" />
    <axis xyz="0 0 1" />
    <limit lower="-1.54" upper="0.0" effort="23" velocity="10.157816247" />
  </joint>
  <link name="L_elbow_link">
    <inertial>
      <origin xyz="-0.0053119 -0.001467 -0.023324" rpy="0 0 0" />
      <mass value="0.4" />
      <inertia ixx="0.0007239" ixy="4E-07" ixz="1.24E-05" iyy="0.001024" iyz="-1.61E-05" izz="0.0006852" />
    </inertial>
    <visual>
      <origin xyz="0 0 0" rpy="0 0 1.57" />
      <geometry>
        <mesh filename="meshes/L_elbow_link.STL" />
      </geometry>
      <material name="">
        <color rgba="0.79216 0.81961 0.93333 1" />
      </material>
    </visual>
    <collision>
      <origin xyz="0 0 0" rpy="0 1.570796327 0" />
      <geometry>
        <cylinder radius="0.04" length="0.07"/>
      </geometry>
    </collision>
  </link>
  <!-- CRA-RI50-70 -->
  <joint name="L_elbow_joint" type="revolute">
    <origin xyz="0 0 0" rpy="0 0 0" />
    <parent link="L_shoulder_yaw_link" />
    <child link="L_elbow_link" />
    <axis xyz="0 1 0" />
    <limit lower="-2.0" upper="0" effort="23" velocity="10.157816247" />
  </joint>
  <link name="L_forearm_yaw_link">
    <inertial>
      <origin xyz="-0.0030164 -0.0002166 0.09188" rpy="0 0 0" />
      <mass value="1.1" />
      <inertia ixx="0.01106" ixy="1.3E-06" ixz="0.0002007" iyy="0.011224" iyz="2.61E-05" izz="0.0008067" />
    </inertial>
    <visual>
      <origin xyz="0 0 0" rpy="0 0 0" />
      <geometry>
        <mesh filename="meshes/L_forearm_yaw_link.STL" />
      </geometry>
      <material name="">
        <color rgba="0.79216 0.81961 0.93333 1" />
      </material>
    </visual>
    <collision>
      <origin xyz="0 0 0.082" rpy="0 0 0" />
      <geometry>
        <cylinder radius="0.035" length="0.13"/>
      </geometry>
    </collision>
  </link>
  <!-- CRA-RI40-52 -->
  <joint name="L_forearm_yaw_joint" type="revolute">
    <origin xyz="0 0 -0.21099" rpy="0 0 0" />
    <parent link="L_elbow_link" />
    <child link="L_forearm_yaw_link" />
    <axis xyz="0 0 1" />
    <limit lower="-1.57" upper="1.57" effort="8.3" velocity="12.356931104" />
  </joint>
  <link name="L_wrist_roll_link">
    <inertial>
      <origin xyz="-0.0021241 -0.0018773 -1.03E-05" rpy="0 0 0" />
      <mass value="0.28" />
      <inertia ixx="9.43E-05" ixy="1E-07" ixz="0" iyy="9.36E-05" iyz="0" izz="0.0001213" />
    </inertial>
    <visual>
      <origin xyz="0 0 0" rpy="0 0 0" />
      <geometry>
        <mesh filename="meshes/L_wrist_roll_link.STL" />
      </geometry>
      <material name="">
        <color rgba="0.79216 0.81961 0.93333 1" />
      </material>
    </visual>
    <collision>
      <origin xyz="0 0 0" rpy="0 1.570796327 0" />
      <geometry>
        <cylinder radius="0.015" length="0.01"/>
      </geometry>
    </collision>
  </link>
  <!-- CRA-RI30-40 -->
  <joint name="L_wrist_roll_joint" type="revolute">
    <origin xyz="0 0 0" rpy="0 0 0" />
    <parent link="L_forearm_yaw_link" />
    <child link="L_wrist_roll_link" />
    <axis xyz="1 0 0" />
    <limit lower="-0.785" upper="0.785" effort="3.3" velocity="12.356931104" />
  </joint>
  <link name="L_wrist_yaw_link">
    <inertial>
      <origin xyz="-6.6E-06 -0.0021885 -0.1128848" rpy="0 0 0" />
      <mass value="0.82" />
      <inertia ixx="0.0043724" ixy="-1E-07" ixz="-4E-07" iyy="0.0043269" iyz="3.07E-05" izz="0.0001196" />
    </inertial>
    <visual>
      <origin xyz="0 0 0" rpy="0 0 0" />
      <geometry>
        <mesh filename="meshes/L_wrist_yaw_link.STL" />
      </geometry>
      <material name="">
        <color rgba="0.79216 0.81961 0.93333 1" />
      </material>
    </visual>
    <collision>
      <origin xyz="0 0 -0.16" rpy="0 0 0" />
      <geometry>
        <box size="0.06 0.03 0.18"/>
      </geometry>
    </collision>
  </link>
  <!-- CRA-RI30-40 -->
  <joint name="L_wrist_yaw_joint" type="revolute">
    <origin xyz="0 0 0" rpy="0 0 0" />
    <parent link="L_wrist_roll_link" />
    <child link="L_wrist_yaw_link" />
    <axis xyz="0 0 1" />
    <limit lower="-0.785" upper="0.785" effort="3.3" velocity="12.356931104" />
  </joint>
<!-- Right arm -->
  <link name="R_shoulder_pitch_link">
    <inertial>
      <origin xyz="-0.0033465 0.010925 -1.3E-06" rpy="0 0 0" />
      <mass value="1.52" />
      <inertia ixx="0.002528" ixy="5E-07" ixz="0" iyy="0.0015489" iyz="3E-07" izz="0.0023225" />
    </inertial>
    <visual>
      <origin xyz="0 0 0" rpy="0.2618 0 0" />
      <geometry>
        <mesh filename="meshes/R_shoulder_pitch_link.STL" />
      </geometry>
      <material name="">
        <color rgba="0.79216 0.81961 0.93333 1" />
      </material>
    </visual>
    <collision>
      <origin xyz="0 0 0" rpy="1.570796327 0 1.570796327"/>
      <geometry>
        <cylinder radius="0.045" length="0.07"/>
      </geometry>
    </collision>
  </link>
  <!-- CRA-RI60-80 -->
  <joint name="R_shoulder_pitch_joint" type="revolute">
    <origin xyz="0 -0.21252 0.3773" rpy="-0.2618 0 0" />
    <parent link="torso_link" />
    <child link="R_shoulder_pitch_link" />
    <axis xyz="0 1 0" />
    <limit lower="-1.57" upper="1.57" effort="42" velocity="8.58701992" />
  </joint>
  <link name="R_shoulder_roll_link">
    <inertial>
      <origin xyz="-0.00325 -0.0010638 -0.057653" rpy="0 0 0" />
      <mass value="0.75" />
      <inertia ixx="0.0047763" ixy="4E-07" ixz="1.89E-05" iyy="0.0052239" iyz="-1.01E-05" izz="0.0014126" />
    </inertial>
    <visual>
      <origin xyz="0 0 0" rpy="0.2618 0 0" />
      <geometry>
        <mesh filename="meshes/R_shoulder_roll_link.STL" />
      </geometry>
      <material name="">
        <color rgba="0.79216 0.81961 0.93333 1" />
      </material>
    </visual>
    <collision>
      <origin xyz="0 0.001 -0.09" rpy="0.2618 0 0" />
      <geometry>
        <cylinder radius="0.04" length="0.07"/>
      </geometry>
    </collision>
  </link>
  <!-- CRA-RI60-80 -->
  <joint name="R_shoulder_roll_joint" type="revolute">
    <origin xyz="0 0 0" rpy="0 0 0" />
    <parent link="R_shoulder_pitch_link" />
    <child link="R_shoulder_roll_link" />
    <axis xyz="1 0 0" />
    <limit lower="-0.785" upper="0.785" effort="42" velocity="8.58701992" />
  </joint>
  <link name="R_shoulder_yaw_link">
    <inertial>
      <origin xyz="-0.003167 0.0008258 0.048204" rpy="0 0 0" />
      <mass value="1.87" />
      <inertia ixx="0.010036" ixy="3E-07" ixz="2.6E-06" iyy="0.0099449" iyz="-7.31E-05" izz="0.0016814" />
    </inertial>
    <visual>
      <origin xyz="0 0 0" rpy="0 0 1.54" />
      <geometry>
        <mesh filename="meshes/R_shoulder_yaw_link.STL" />
      </geometry>
      <material name="">
        <color rgba="0.79216 0.81961 0.93333 1" />
      </material>
    </visual>
    <collision>
      <origin xyz="0 0 0.08" rpy="0 0 0" />
      <geometry>
        <cylinder radius="0.04" length="0.07"/>
        <!-- <mesh filename="meshes/R_shoulder_yaw_link.STL" /> -->
      </geometry>
    </collision>
  </link>
  <!-- CRA-RI50-70 -->
  <joint name="R_shoulder_yaw_joint" type="revolute">
    <origin xyz="0 0.043208 -0.25042" rpy="0.2618 0 0" />
    <!-- <origin xyz="0 0.043208 -0.25042" rpy="0.2618 0 0" /> -->
    <parent link="R_shoulder_roll_link" />
    <child link="R_shoulder_yaw_link" />
    <axis xyz="0 0 1" />
    <limit lower="0" upper="1.57" effort="23" velocity="10.157816247" />
  </joint>
  <link name="R_elbow_link">
    <inertial>
      <origin xyz="-0.0053221 0.0014743 -0.023308" rpy="0 0 0" />
      <mass value="0.4" />
      <inertia ixx="0.0007239" ixy="-5E-07" ixz="1.21E-05" iyy="0.0010239" iyz="1.6E-05" izz="0.0006853" />
    </inertial>
    <visual>
      <origin xyz="0 0 0" rpy="0 0 -1.57" />
      <geometry>
        <mesh filename="meshes/R_elbow_link.STL" />
      </geometry>
      <material name="">
        <color rgba="0.79216 0.81961 0.93333 1" />
      </material>
    </visual>
    <collision>
      <origin xyz="0 0 0" rpy="0 1.570796327 0" />
      <geometry>
        <cylinder radius="0.04" length="0.07"/>
      </geometry>
    </collision>
  </link>
  <!-- CRA-RI50-70 -->
  <joint name="R_elbow_joint" type="revolute">
    <origin xyz="0 0 0" rpy="0 0 0" />
    <parent link="R_shoulder_yaw_link" />
    <child link="R_elbow_link" />
    <axis xyz="0 1 0" />
    <limit lower="-2" upper="0" effort="23" velocity="10.157816247" />
  </joint>
  <link name="R_forearm_yaw_link">
    <inertial>
      <origin xyz="-0.0030168 0.0002163 0.09188" rpy="0 0 0" />
      <mass value="1.1" />
      <inertia ixx="0.01106" ixy="-1.3E-06" ixz="0.0002008" iyy="0.011224" iyz="-2.61E-05" izz="0.0008067" />
    </inertial>
    <visual>
      <origin xyz="0 0 0" rpy="0 0 0" />
      <geometry>
        <mesh filename="meshes/R_forearm_yaw_link.STL" />
      </geometry>
      <material name="">
        <color rgba="0.79216 0.81961 0.93333 1" />
      </material>
    </visual>
    <collision>
      <origin xyz="0 0 0.082" rpy="0 0 0" />
      <geometry>
        <cylinder radius="0.035" length="0.13"/>
      </geometry>
    </collision>
  </link>
  <!-- CRA-RI40-52 -->
  <joint name="R_forearm_yaw_joint" type="revolute">
    <origin xyz="0 0 -0.21099" rpy="0 0 0" />
    <parent link="R_elbow_link" />
    <child link="R_forearm_yaw_link" />
    <axis xyz="0 0 1" />
    <limit lower="-1.57" upper="1.57" effort="8.3" velocity="12.356931104" />
  </joint>
  <link name="R_wrist_roll_link">
    <inertial>
      <origin xyz="-0.0021241 0.0018773 -1.0333E-05" rpy="0 0 0" />
      <mass value="0.28" />
      <inertia ixx="9.43E-05" ixy="-1E-07" ixz="0" iyy="9.36E-05" iyz="0" izz="0.0001213" />
    </inertial>
    <visual>
      <origin xyz="0 0 0" rpy="0 0 0" />
      <geometry>
        <mesh filename="meshes/R_wrist_roll_link.STL" />
      </geometry>
      <material name="">
        <color rgba="0.79216 0.81961 0.93333 1" />
      </material>
    </visual>
    <collision>
      <origin xyz="0 0 0" rpy="0 1.570796327 0" />
      <geometry>
        <cylinder radius="0.015" length="0.01"/>
      </geometry>
    </collision>
  </link>
  <!-- CRA-RI30-40 -->
  <joint name="R_wrist_roll_joint" type="revolute">
    <origin xyz="0 0 0" rpy="0 0 0" />
    <parent link="R_forearm_yaw_link" />
    <child link="R_wrist_roll_link" />
    <axis xyz="1 0 0" />
    <limit lower="-0.785" upper="0.785" effort="3.3" velocity="12.356931104" />
  </joint>
  <link name="R_wrist_yaw_link">
    <inertial>
      <origin xyz="-6.6E-06 -0.0021885 -0.1128848" rpy="0 0 0" />
      <mass value="0.82" />
      <inertia ixx="0.0043724" ixy="-1E-07" ixz="-4E-07" iyy="0.0043269" iyz="-3.07E-05" izz="0.0001196" />
    </inertial>
    <visual>
      <origin xyz="0 0 0" rpy="0 0 0" />
      <geometry>
        <mesh filename="meshes/R_wrist_yaw_link.STL" />
      </geometry>
      <material name="">
        <color rgba="0.79216 0.81961 0.93333 1" />
      </material>
    </visual>
    <collision>
      <origin xyz="0 0 -0.16" rpy="0 0 0" />
      <geometry>
        <box size="0.06 0.03 0.18"/>
      </geometry>
    </collision>
  </link>
  <!-- CRA-RI30-40 -->
  <joint name="R_wrist_yaw_joint" type="revolute">
    <origin xyz="0 0 0" rpy="0 0 0" />
    <parent link="R_wrist_roll_link" />
    <child link="R_wrist_yaw_link" />
    <axis xyz="0 1 0" />
    <limit lower="-0.785" upper="0.785" effort="3.3" velocity="12.356931104" />
  </joint>
<!-- pelvis -->
  <link name="pelvis_link">
    <inertial>
      <origin xyz="-0.06477 1.18E-05 -0.058888" rpy="0 0 0" />
      <mass value="4.73" />
      <inertia ixx="0.056862" ixy="1.05E-05" ixz="-0.019234" iyy="0.050447" iyz="3.13E-05" izz="0.06205" />
    </inertial>
    <visual>
      <origin xyz="0 0 0" rpy="0 0 0" />
      <geometry>
        <mesh filename="meshes/pelvis_link.STL" />
      </geometry>
      <material name="">
        <color rgba="0.79216 0.81961 0.93333 1" />
      </material>
    </visual>
    <collision>
      <origin xyz="-0.1 0 -0.05" rpy="0 0 0" />
      <geometry>
        <box size="0.08 0.35 0.1"/>
      </geometry>
    </collision>

  </link>
  <!-- CRA-RI60-80 -->
  <joint name="pelvis_joint" type="revolute">
    <origin xyz="0 0 0" rpy="0 0 0" />
    <parent link="torso_link" />
    <child link="pelvis_link" />
    <axis xyz="0 0 1" />
    <limit lower="-1.0472" upper="1.0472" effort="42" velocity="8.58701992" />
  </joint>
<!-- Left leg -->
  <link name="L_hip_roll_link">
    <inertial>
      <origin xyz="-0.013998 2.53E-05 0.0052806" rpy="0 0 0" />
      <mass value="1.23" />
      <inertia ixx="0.0012551" ixy="5E-07" ixz="9.38E-05" iyy="0.0018636" iyz="-1.5E-06" izz="0.0023136" />
    </inertial>
    <visual>
      <origin xyz="0 0 0" rpy="0 0 0" />
      <geometry>
        <mesh filename="meshes/L_hip_roll_link.STL" />
      </geometry>
      <material name="">
        <color rgba="0.79216 0.81961 0.93333 1" />
      </material>
    </visual>
    <collision>
      <origin xyz="0 0 0" rpy="0 0 0" />
      <geometry>
        <!-- <mesh filename="meshes/L_hip_roll_link.STL" /> -->
        <cylinder radius="0.05" length="0.07"/>
      </geometry>
    </collision>
  </link>
  <!-- EC-A8112-P1-18 -->
  <joint name="L_hip_roll_joint" type="revolute">
    <origin xyz="0 0.115 -0.063238" rpy="0 0 0" />
    <parent link="pelvis_link" />
    <child link="L_hip_roll_link" />
    <axis xyz="1 0 0" />
    <limit lower="-0.0873" upper="0.7854" effort="90" velocity="16.441001554" />
  </joint>
  <link name="L_hip_yaw_link">
    <inertial>
      <origin xyz="-2.7849E-05 -0.0008477 -0.11745" rpy="0 0 0" />
      <mass value="3.64" />
      <inertia ixx="0.064593" ixy="-1.18E-05" ixz="-1.18E-05" iyy="0.067332" iyz="-0.0004132" izz="0.0086965" />
    </inertial>
    <visual>
      <origin xyz="0 0 0" rpy="0 0 0" />
      <geometry>
        <mesh filename="meshes/L_hip_yaw_link.STL" />
      </geometry>
      <material name="">
        <color rgba="0.79216 0.81961 0.93333 1" />
      </material>
    </visual>
    <collision>
      <origin xyz="-2.7849E-05 -0.0008477 -0.05745" rpy="0 0 0" />
      <geometry>
        <cylinder radius="0.05" length="0.03"/>
      </geometry>
    </collision>
    <collision>
      <origin xyz="-2.7849E-05 -0.0008477 -0.11745" rpy="1.570796327 0 0" />
      <geometry>
        <cylinder radius="0.045" length="0.09"/>
      </geometry>
    </collision>
  </link>
  <!-- EC-6408-P2-25 -->
  <joint name="L_hip_yaw_joint" type="revolute">
    <origin xyz="0 0 0" rpy="0 0 0" />
    <parent link="L_hip_roll_link" />
    <child link="L_hip_yaw_link" />
    <axis xyz="0 0 1" />
    <limit lower="-0.6981" upper="0.6981" effort="60" velocity="15.603243513" />
  </joint>
  <link name="L_hip_pitch_link">
    <inertial>
      <origin xyz="0.0098233 0.0015198 -0.1287" rpy="0 0 0" />
      <mass value="1.93" />
      <inertia ixx="0.063751" ixy="-6.84E-05" ixz="0.0029693" iyy="0.062732" iyz="-7.3E-05" izz="0.0085832" />
    </inertial>
    <visual>
      <origin xyz="0 0 0" rpy="0 0 0" />
      <geometry>
        <mesh filename="meshes/L_hip_pitch_link.STL" />
      </geometry>
      <material name="">
        <color rgba="0.79216 0.81961 0.93333 1" />
      </material>
    </visual>
    <collision>
      <origin xyz="0 0 -0.12" rpy="0 0 0" />
      <geometry>
        <!-- <mesh filename="meshes/L_hip_pitch_link.STL" /> -->
        <cylinder radius="0.045" length="0.18"/>
      </geometry>
    </collision>
  </link>
  <!-- EC-A10020-P2-24 -->
  <joint name="L_hip_pitch_joint" type="revolute">
    <origin xyz="0 0 -0.14" rpy="0 0 0" />
    <parent link="L_hip_yaw_link" />
    <child link="L_hip_pitch_link" />
    <axis xyz="0 1 0" />
    <limit lower="-1.6581" upper="0.8727" effort="330" velocity="12.88052988" />
  </joint>
  <link name="L_knee_link">
    <inertial>
      <origin xyz="0.0068711 0.0034967 -0.11181" rpy="0 0 0" />
      <mass value="6" />
      <inertia ixx="0.1956" ixy="-0.0001392" ixz="0.0066738" iyy="0.19917" iyz="0.0025104" izz="0.012547" />
    </inertial>
    <visual>
      <origin xyz="0 0 0" rpy="0 0 0" />
      <geometry>
        <mesh filename="meshes/L_knee_link.STL" />
      </geometry>
      <material name="">
        <color rgba="0.79216 0.81961 0.93333 1" />
      </material>
    </visual>
    <collision>
      <origin xyz="0 0 -0.19" rpy="0 0 0" />
      <geometry>
        <cylinder radius="0.045" length="0.2"/>
      </geometry>
    </collision>
    <collision>
      <origin xyz="0 0 -0.35" rpy="0 0 0" />
      <geometry>
        <cylinder radius="0.025" length="0.1"/>
      </geometry>
    </collision>
    <collision>
      <origin xyz="0 0 0.0" rpy="1.570796327 0 0" />
      <geometry>
        <cylinder radius="0.065" length="0.1"/>
      </geometry>
    </collision>
  </link>
  <!-- EC-A10020-P2-24 -->
  <joint name="L_knee_joint" type="revolute">
    <origin xyz="0 -0.00083747 -0.28496" rpy="0 0 0" />
    <parent link="L_hip_pitch_link" />
    <child link="L_knee_link" />
    <axis xyz="0 1 0" />
    <limit lower="-0.0873" upper="2.3562" effort="330" velocity="12.88052988" />
  </joint>
  <link name="L_ankle_pitch_link">
    <inertial>
      <origin xyz="0 5.1067E-05 -0.0029071" rpy="0 0 0" />
      <mass value="0.05" />
      <inertia ixx="4.7E-06" ixy="0" ixz="0" iyy="4.3E-06" iyz="0" izz="3.7E-06" />
    </inertial>
    <visual>
      <origin xyz="0 0 0" rpy="0 0 0" />
      <geometry>
        <mesh filename="meshes/L_ankle_pitch_link.STL" />
      </geometry>
      <material name="">
        <color rgba="0.79216 0.81961 0.93333 1" />
      </material>
    </visual>
    <collision>
      <origin xyz="0 0 0" rpy="0 0 0" />
      <geometry>
        <cylinder radius="0.001" length="0.001"/>
        <!-- <mesh filename="meshes/L_ankle_pitch_link.STL" /> -->
      </geometry>
    </collision>
  </link>
  <!-- EC-A4310-P2-36 -->
  <joint name="L_ankle_pitch_joint" type="revolute">
    <origin xyz="0 0 -0.45087" rpy="0 0 0" />
    <parent link="L_knee_link" />
    <child link="L_ankle_pitch_link" />
    <axis xyz="0 1 0" />
    <limit lower="-0.4363" upper="0.4363" effort="36" velocity="9.320058206" />
  </joint>
  <link name="L_ankle_roll_link">
    <inertial>
      <origin xyz="-0.030805 0.00039115 -0.033202" rpy="0 0 0" />
      <mass value="1.29" />
      <inertia ixx="0.0023411" ixy="0.0000146" ixz="0.0015349" iyy="0.0083543" iyz="0.0000164" izz="0.0074941" />
    </inertial>
    <visual>
      <origin xyz="0 0 0" rpy="0 0 0" />
      <geometry>
        <mesh filename="meshes/L_ankle_roll_link.STL" />
      </geometry>
      <material name="">
        <color rgba="0.79216 0.81961 0.93333 1" />
      </material>
    </visual>
    <collision>
      <origin xyz="0 0 -0.02" rpy="0 0 0" />
      <geometry>
        <cylinder radius="0.01" length="0.01"/>
        <!-- <mesh filename="meshes/L_ankle_roll_link.STL" /> -->
      </geometry>
    </collision>
    <collision>
      <origin xyz="0 0 0" rpy="0 0 0" />
      <geometry>
        <mesh filename="meshes/L_ankle_roll_link.STL" />
      </geometry>
    </collision>
  </link>
  <!-- EC-A4310-P2-36 -->
  <joint name="L_ankle_roll_joint" type="revolute">
    <origin xyz="0 0 0" rpy="0 0 0" />
    <parent link="L_ankle_pitch_link" />
    <child link="L_ankle_roll_link" />
    <axis xyz="1 0 0" />
    <limit lower="-0.3491" upper="0.3491" effort="36" velocity="9.320058206" />
  </joint>
<!-- Right leg -->
  <link name="R_hip_roll_link">
    <inertial>
      <origin xyz="-0.013997 -2.54E-05 0.0052806" rpy="0 0 0" />
      <mass value="1.23" />
      <inertia ixx="0.0012551" ixy="-5E-07" ixz="9.38E-06" iyy="0.0018636" iyz="1.5E-06" izz="0.0023136" />
    </inertial>
    <visual>
      <origin xyz="0 0 0" rpy="0 0 0" />
      <geometry>
        <mesh filename="meshes/R_hip_roll_link.STL" />
      </geometry>
      <material name="">
        <color rgba="0.79216 0.81961 0.93333 1" />
      </material>
    </visual>
    <collision>
      <origin xyz="0 0 0" rpy="0 0 0" />
      <geometry>
        <!-- <mesh filename="meshes/R_hip_roll_link.STL" /> -->
        <cylinder radius="0.05" length="0.07"/>
      </geometry>
    </collision>
  </link>
  <!-- EC-A8112-P1-18 -->
  <joint name="R_hip_roll_joint" type="revolute">
    <origin xyz="0 -0.115 -0.063238" rpy="0 0 0" />
    <parent link="pelvis_link" />
    <child link="R_hip_roll_link" />
    <axis xyz="1 0 0" />
    <limit lower="-0.7854" upper="0.0873" effort="90" velocity="16.441001554" />
  </joint>
  <link name="R_hip_yaw_link">
    <inertial>
      <origin xyz="-2.68E-05 0.00084756 -0.11745" rpy="0 0 0" />
      <mass value="3.64" />
      <inertia ixx="0.064594" ixy="1.18E-05" ixz="-1.15E-05" iyy="0.067332" iyz="0.0004131" izz="0.0086964" />
    </inertial>
    <visual>
      <origin xyz="0 0 0" rpy="0 0 0" />
      <geometry>
        <mesh filename="meshes/R_hip_yaw_link.STL" />
      </geometry>
      <material name="">
        <color rgba="0.79216 0.81961 0.93333 1" />
      </material>
    </visual>
    <collision>
      <origin xyz="-2.7849E-05 -0.0008477 -0.11745" rpy="1.570796327 0 0" />
      <geometry>
        <cylinder radius="0.045" length="0.09"/>
      </geometry>
    </collision>
  </link>
  <!-- EC-6408-P2-25 -->
  <joint name="R_hip_yaw_joint" type="revolute">
    <origin xyz="0 0 0" rpy="0 0 0" />
    <parent link="R_hip_roll_link" />
    <child link="R_hip_yaw_link" />
    <axis xyz="0 0 1" />
    <limit lower="-0.6981" upper="0.6981" effort="60" velocity="15.603243513" />
  </joint>
  <link name="R_hip_pitch_link">
    <inertial>
      <origin xyz="0.0097967 -0.0015629 -0.1287" rpy="0 0 0" />
      <mass value="1.93" />
      <inertia ixx="0.063726" ixy="6.79E-05" ixz="0.0029655" iyy="0.062707" iyz="6.78E-05" izz="0.0085829" />
    </inertial>
    <visual>
      <origin xyz="0 0 0" rpy="0 0 0" />
      <geometry>
        <mesh filename="meshes/R_hip_pitch_link.STL" />
      </geometry>
      <material name="">
        <color rgba="0.79216 0.81961 0.93333 1" />
      </material>
    </visual>
    <collision>
      <origin xyz="0 0 -0.12" rpy="0 0 0" />
      <geometry>
        <!-- <mesh filename="meshes/R_hip_pitch_link.STL" /> -->
        <cylinder radius="0.045" length="0.18"/>
      </geometry>
    </collision>
  </link>
  <!-- EC-A10020-P2-24 -->
  <joint name="R_hip_pitch_joint" type="revolute">
    <origin xyz="0 0 -0.14" rpy="0 0 0" />
    <parent link="R_hip_yaw_link" />
    <child link="R_hip_pitch_link" />
    <axis xyz="0 1 0" />
    <limit lower="-1.6581" upper="0.8727" effort="330" velocity="12.88052988" />
  </joint>
  <link name="R_knee_link">
    <inertial>
      <origin xyz="0.0068724 -0.0034964 -0.11181" rpy="0 0 0" />
      <mass value="6" />
      <inertia ixx="0.19557" ixy="0.0001394" ixz="0.0066728" iyy="0.19914" iyz="-0.0025101" izz="0.012547" />
    </inertial>
    <visual>
      <origin xyz="0 0 0" rpy="0 0 0" />
      <geometry>
        <mesh filename="meshes/R_knee_link.STL" />
      </geometry>
      <material name="">
        <color rgba="0.79216 0.81961 0.93333 1" />
      </material>
    </visual>
    <collision>
      <origin xyz="0 0 -0.19" rpy="0 0 0" />
      <geometry>
        <cylinder radius="0.045" length="0.2"/>
      </geometry>
    </collision>
    <collision>
      <origin xyz="0 0 -0.35" rpy="0 0 0" />
      <geometry>
        <cylinder radius="0.025" length="0.1"/>
      </geometry>
    </collision>
    <collision>
      <origin xyz="0 0 0.0" rpy="1.570796327 0 0" />
      <geometry>
        <cylinder radius="0.065" length="0.1"/>
      </geometry>
    </collision>
  </link>
  <!-- EC-A10020-P2-24 -->
  <joint name="R_knee_joint" type="revolute">
    <origin xyz="0 0.00083747 -0.28496" rpy="0 0 0" />
    <parent link="R_hip_pitch_link" />
    <child link="R_knee_link" />
    <axis xyz="0 1 0" />
    <limit lower="-0.0873" upper="2.3562" effort="330" velocity="12.88052988" />
  </joint>
  <link name="R_ankle_pitch_link">
    <inertial>
      <origin xyz="0 -5.1111E-05 -0.0029071" rpy="0 0 0" />
      <mass value="0.05" />
      <inertia ixx="4.7E-06" ixy="0" ixz="0" iyy="4.3E-06" iyz="0" izz="3.7E-06" />
    </inertial>
    <visual>
      <origin xyz="0 0 0" rpy="0 0 0" />
      <geometry>
        <mesh filename="meshes/R_ankle_pitch_link.STL" />
      </geometry>
      <material name="">
        <color rgba="0.79216 0.81961 0.93333 1" />
      </material>
    </visual>
    <collision>
      <origin xyz="0 0 0" rpy="0 0 0" />
      <geometry>
        <cylinder radius="0.001" length="0.001"/>
      </geometry>
    </collision>
  </link>
  <!-- EC-A4310-P2-36 -->
  <joint name="R_ankle_pitch_joint" type="revolute">
    <origin xyz="0 0 -0.45087" rpy="0 0 0" />
    <parent link="R_knee_link" />
    <child link="R_ankle_pitch_link" />
    <axis xyz="0 1 0" />
    <limit lower="-0.4363" upper="0.4363" effort="36" velocity="9.320058206" />
  </joint>
  <link name="R_ankle_roll_link">
    <inertial>
      <origin xyz="-0.030805 -0.00039115 -0.033202" rpy="0 0 0" />
      <mass value="1.29" />
      <inertia ixx="0.0023411" ixy="-0.0000146" ixz="0.0015349" iyy="0.0083543" iyz="0.0000164" izz="0.0074941" />
    </inertial>
    <visual>
      <origin xyz="0 0 0" rpy="0 0 0" />
      <geometry>
        <mesh filename="meshes/R_ankle_roll_link.STL" />
      </geometry>
      <material name="">
        <color rgba="0.79216 0.81961 0.93333 1" />
      </material>
    </visual>
    <collision>
      <origin xyz="0 0 0" rpy="0 0 0" />
      <geometry>
        <mesh filename="meshes/R_ankle_roll_link.STL" />
      </geometry>
    </collision>
  </link>
  <!-- EC-A4310-P2-36 -->
  <joint name="R_ankle_roll_joint" type="revolute">
    <origin xyz="0 0 0" rpy="0 0 0" />
    <parent link="R_ankle_pitch_link" />
    <child link="R_ankle_roll_link" />
    <axis xyz="1 0 0" />
    <limit lower="-0.3491" upper="0.3491" effort="36" velocity="9.320058206" />
  </joint>
<!-- Head -->
  <link name="head_yaw_link">
    <inertial>
      <origin xyz="-0.00011265 -0.0013901 -0.0044247" rpy="0 0 0" />
      <mass value="0.6" />
      <inertia ixx="0.0009244" ixy="-1E-07" ixz="-3E-07" iyy="0.0002027" iyz="2E-07" izz="0.0009019" />
    </inertial>
    <visual>
      <origin xyz="0 0 0" rpy="0 0 0" />
      <geometry>
        <mesh filename="meshes/head_yaw_link.STL" />
      </geometry>
      <material name="">
        <color rgba="0.79216 0.81961 0.93333 1" />
      </material>
    </visual>
    <collision>
      <origin xyz="0 0 0" rpy="0 0 0" />
      <geometry>
        <box size="0.01 0.01 0.01"/>
      </geometry>
    </collision>
  </link>
  <joint name="head_yaw_joint" type="revolute">
    <origin xyz="0.012 0 0.6048" rpy="0 0 0" />
    <parent link="torso_link" />
    <child link="head_yaw_link" />
    <axis xyz="0 0 1" />
    <limit lower="-1.57" upper="1.57" effort="2.52" velocity="29.216811679" />
  </joint>
  <link name="head_pitch_link">
    <inertial>
      <origin xyz="0.021311 0.00077107 0.028434" rpy="0 0 0" />
      <mass value="0.3" />
      <inertia ixx="0.0030558" ixy="4.26E-05" ixz="0.0002171" iyy="0.0040773" iyz="-1.19E-05" izz="0.0035202" />
    </inertial>
    <visual>
      <origin xyz="0 0 0" rpy="0 0 0" />
      <geometry>
        <mesh filename="meshes/head_pitch_link.STL" />
      </geometry>
      <material name="">
        <color rgba="0.79216 0.81961 0.93333 1" />
      </material>
    </visual>
    <collision>
      <origin xyz="0.05 0 0" rpy="0 0 0" />
      <geometry>
        <box size="0.01 0.12 0.12"/>
      </geometry>
    </collision>
  </link>
  <joint name="head_pitch_joint" type="revolute">
    <origin xyz="0 0 0" rpy="0 0 0" />
    <parent link="head_yaw_link" />
    <child link="head_pitch_link" />
    <axis xyz="0 1 0" />
    <limit lower="-0.785" upper="0.157" effort="1.26" velocity="58.433623357" />
  </joint>
</robot>