<mujoco>
  <include file="common/scene.xml"/>
  <option timestep="0.001" />
  <asset>
    <material name="blue_" rgba="0 0 1 0.6" />
    <material name="green" rgba="0 1 0 0.6" />
    <material name="red__" rgba="1 0 0 0.1" />
    <material name="white" rgba="1 1 1 0.8" />
    <material name="black" rgba="0 0 0 0.8" />
  </asset>
  <compiler angle="degree" />
    
  <worldbody>
    <light diffuse=".5 .5 .5" pos="0 0 3" dir="0 0 -1" />
    <body name="calf" pos="0 0 9">
      <light name="spotlight" mode="trackcom" pos="0 -2 50" dir="0 0 -1"/>
      <geom type="box" size="0.5 0.5 1.5" pos="0 0 0" euler="0 0 0" material="red__" />
      <body name="Flange_A" pos="0 0 2.5" euler="0 0 0">
      <!-- pos 的 2.5 是d/2 -->
        <geom type="box" size="0.5 .1 .2" pos="-0.5 1.2 0" euler="0 0 0" material="blue_" />
        <!-- size的0.5是a/2 pos的-0.5是-a/2 1.2是b -->
        <joint name="Flange_A_joint" pos="0 0 0" axis="0 1 0" range="-80 80" actuatorfrcrange="-200 200"/>
        <body name="Rod_A" pos="-1 1.2 0" euler="0 0 0">
        <!-- pos的-1是-a,1.2是b -->
          <geom type="box" size="0.2 .2 2." pos="0. 0. -2.5" euler="0 0 0" material="green" />
          <!-- size的2.5是d/2,pos的2.5是-d/2 -->
          <joint name="Rod_A_joint" type="ball" pos="0 0 0"/>
        </body>
      </body>
      <body name="Flange_B" pos="0 0 0.5" euler="0 0 0">
      <!-- pos 的 0.5 是c-d/2 -->
        <geom type="box" size="0.5 .1 .2" pos="-0.5 -1.2 0" euler="0 0 0" material="blue_" />
        <!-- size的0.5是a/2 pos的-0.5是-a/2 -1.2是-b -->
        <joint name="Flange_B_joint" pos="0 0 0" axis="0 1 0" range="-80 80" actuatorfrcrange="-200 200"/>
        <body name="Rod_B" pos="-1 -1.2 0" euler="0 0 0">
        <!-- pos的-1是-a,-1.2是-b -->
          <geom type="box" size="0.2 .2 1." pos="0. 0. -1.5" euler="0 0 0" material="green" />
          <!-- size的1.5是c/2,pos的1.5是-c/2 -->
          <joint name="Rod_B_joint" type="ball" pos="0 0 0"/>
        </body>
      </body>
      <body name="Ankle_pitch" pos="0 0 -2.5" euler="0 0 0">
      <!-- pos的-2.5是-d/2 -->
        <geom type="box" size="0.5 .1 .1" pos="-0.5 0 0" euler="0 0 0" material="white" />
        <!-- size的0.5是a/2,pos的-0.5是-a/2 -->
        <joint name="Ankle_pitch_joint" pos="0 0 0" axis="0 1 0" range="-80 80" actuatorfrcrange="-200 200"/>
        <body name="Ankle_roll" pos="-1 0 0" euler="0 0 0">
        <!-- pos的-1是-a -->
          <geom type="box" size=".1 1.2 .1" pos="0 0 0" euler="0 0 0" material="black" />
          <!-- size的1.2是b -->
          <joint name="Ankle_roll_joint" pos="0 0 0" axis="1 0 0" range="-80 80" actuatorfrcrange="-200 200"/>
        </body>
      </body>

    </body>
  </worldbody>
  <actuator>
    <motor joint="Flange_A_joint" name="Flange_A_joint" ctrlrange="-300 300" ctrllimited="true"/>
    <motor joint="Flange_B_joint" name="Flange_B_joint" ctrlrange="-300 300" ctrllimited="true"/>
  </actuator>
  <equality>
    <!-- <weld name="Ankle_roll_Rod_A" body1="Ankle_roll" body2="Rod_A" torquescale="0"/> -->
    <connect name="Ankle_roll_Rod_A" active="true" body1="Ankle_roll" body2="Rod_A" anchor="0 1.2 0" />
    <!-- <weld name="Ankle_roll_Rod_B" body1="Ankle_roll" body2="Rod_B" torquescale="0"/> -->
    <connect name="Ankle_roll_Rod_B" active="true" body1="Ankle_roll" body2="Rod_B" anchor="0 -1.2 0" />
  </equality>
  <contact>
    <!-- <exclude body1="link_1" body2="link_2"/>
    <exclude body1="link_1" body2="link_3"/>
    <exclude body1="link_1" body2="link_4"/>
    <exclude body1="link_2" body2="link_3"/>
    <exclude body1="link_2" body2="link_4"/>
    <exclude body1="link_3" body2="link_4"/> -->
  </contact>
</mujoco>